Workbook

Sheet Dataset
A1: Component Number | B1: Supplier Name | C1: Delivery Timeline (Days) | D1: Raw Material Cost ($) | E1: Risk Level | F1: Mitigation Plan | G1: Supply Chain Expected Date | H1: Defect Rate (%) | I1: Production Usage Rate (Units/Day) | J1: Supplier Reliability (%) | K1: Inventory Level (Units) | L1: Reorder Point (Units) | M1: Lead Time Variance (Days) | N1: Expedite Shipping Cost ($) | O1: Order Size (Units) | P1: On-Time Delivery Rate (%) | Q1: Backorder Volume (Units) | R1: Quality Inspection Pass Rate (%) | S1: Forecast Accuracy (%) | T1: Safety Stock (Units)
A2: BIND567 | B2: EcoSupply | C2: 64 | D2: 1309 | E2: Medium | F2: Negotiate Terms | G2: 2024-12-15 | H2: 2.91 | I2: 1496 | J2: 99 | K2: 25500 | L2: 580 | M2: 26 | N2: 1100 | O2: 2698 | P2: 99 | Q2: 453 | R2: 95 | S2: 98 | T2: 398
A3: CARB123 | B3: RawMatPlus | C3: 62 | D3: 1112 | E3: Medium | F3: Review Contract | G3: 2024-12-15 | H3: 4.41 | I3: 1277 | J3: 97 | K3: 16530 | L3: 1214 | M3: 24 | N3: 1196 | O3: 1569 | P3: 84 | Q3: 110 | R3: 95 | S3: 83 | T3: 347
A4: CARB123 | B4: RawMatPlus | C4: 10 | D4: 1108 | E4: High | F4: Expedite Shipping | G4: 2024-07-21 | H4: 2.56 | I4: 771 | J4: 87 | K4: 20100 | L4: 1262 | M4: 8 | N4: 1603 | O4: 1538 | P4: 98 | Q4: 219 | R4: 99 | S4: 92 | T4: 485
A5: CARB123 | B5: RawMatPlus | C5: 12 | D5: 1046 | E5: Low | F5: Negotiate Terms | G5: 2024-03-21 | H5: 1.22 | I5: 1196 | J5: 91 | K5: 34420 | L5: 565 | M5: 6 | N5: 1281 | O5: 2220 | P5: 94 | Q5: 270 | R5: 94 | S5: 97 | T5: 740
A6: CARB123 | B6: RawMatPlus | C6: 9 | D6: 1393 | E6: High | F6: Increase Inventory | G6: 2024-02-10 | H6: 2.46 | I6: 964 | J6: 85 | K6: 49060 | L6: 1239 | M6: 4 | N6: 1525 | O6: 2560 | P6: 85 | Q6: 259 | R6: 91 | S6: 89 | T6: 730
A7: COAT890 | B7: GlobalChem | C7: 60 | D7: 1125 | E7: Low | F7: Source Alternative | G7: 2024-12-04 | H7: 3.55 | I7: 1413 | J7: 93 | K7: 13560 | L7: 1104 | M7: 22 | N7: 565 | O7: 1061 | P7: 82 | Q7: 111 | R7: 93 | S7: 96 | T7: 608
A8: COAT890 | B8: GlobalChem | C8: 15 | D8: 1116 | E8: Medium | F8: Negotiate Terms | G8: 2024-04-28 | H8: 0.95 | I8: 784 | J8: 92 | K8: 36030 | L8: 1354 | M8: 5 | N8: 833 | O8: 1758 | P8: 91 | Q8: 107 | R8: 94 | S8: 82 | T8: 611
A9: COAT890 | B9: RawMatPlus | C9: 8 | D9: 1083 | E9: Medium | F9: Expedite Shipping | G9: 2024-05-21 | H9: 3.6 | I9: 724 | J9: 95 | K9: 23280 | L9: 1363 | M9: 0 | N9: 969 | O9: 2683 | P9: 81 | Q9: 412 | R9: 95 | S9: 92 | T9: 437
A10: COAT890 | B10: NextGen Pharma | C10: 10 | D10: 1390 | E10: Low | F10: Review Contract | G10: 2024-09-01 | H10: 3.2 | I10: 1000 | J10: 85 | K10: 14580 | L10: 1451 | M10: 5 | N10: 1129 | O10: 1490 | P10: 81 | Q10: 123 | R10: 99 | S10: 82 | T10: 343
A11: COAT890 | B11: GlobalChem | C11: 13 | D11: 1392 | E11: Low | F11: Source Alternative | G11: 2024-11-16 | H11: 4.76 | I11: 669 | J11: 89 | K11: 31610 | L11: 1393 | M11: 9 | N11: 1366 | O11: 2975 | P11: 86 | Q11: 475 | R11: 98 | S11: 86 | T11: 665
A12: COMP010 | B12: PrimeLogistics | C12: 15 | D12: 1332 | E12: Medium | F12: Expedite Shipping | G12: 2024-09-15 | H12: 1.04 | I12: 730 | J12: 86 | K12: 23840 | L12: 521 | M12: 9 | N12: 1634 | O12: 1471 | P12: 98 | Q12: 112 | R12: 90 | S12: 82 | T12: 662
A13: COMP011 | B13: NextGen Pharma | C13: 6 | D13: 1463 | E13: Low | F13: Increase Inventory | G13: 2024-02-17 | H13: 1.57 | I13: 1185 | J13: 92 | K13: 18770 | L13: 1052 | M13: 2 | N13: 1981 | O13: 2915 | P13: 98 | Q13: 295 | R13: 97 | S13: 87 | T13: 701
... A51: COMP049 | B51: NextGen Pharma | C51: 9 | D51: 1304 | E51: High | F51: Review Contract | G51: 2024-05-15 | H51: 1.06 | I51: 1205 | J51: 89 | K51: 38660 | L51: 912 | M51: 4 | N51: 1524 | O51: 2105 | P51: 95 | Q51: 224 | R51: 91 | S51: 99 | T51: 320

Sheet Analysis
A1: Component | B1: Supplier | C1: Supply Chain Receipt Date | D1: Risk Level | E1: Delivery Timeline | F1: Issue Summary | G1: Supplier Analysis | H1: Risk Factors | I1: Component Specific Changes
A2: BIND567 | B2: EcoSupply | C2: 45641 | D2: Medium | E2: 10 days | F2: The component has a confirmed delay, with receipt scheduled close to critical production deadlines. EcoSupply’s reliability and defect rates warrant further review, given the FDA’s emphasis on consistent supply for regulated products. | G2: EcoSupply’s delivery metrics reveal recurring delays for critical components. Supply chain receipt tracking shows an increasing trend of shipment delays over the past quarter. | H2: Medium risk with limited contingency plans. High reliance on EcoSupply’s consistency amplifies vulnerability. | I2: Negotiate expedited shipping terms with EcoSupply. Increase inventory buffer to mitigate future delays.
A3: COMP042 | B3: PrimeLogistics | C3: 45644 | D3: Medium | E3: 13 days | F3: PrimeLogistics has experienced lead time variances that pose additional risks for this component. A 13-day timeline exceeds typical thresholds and may necessitate expedited shipping, potentially increasing costs and reducing margin. | G3: PrimeLogistics’ lead time variance (up to 3 days) indicates weak demand forecasting. | H3: Medium risk with significant variability in supplier performance. | I3: Collaborate with PrimeLogistics on demand planning. Adjust order cycles to account for lead time variances.
A4: COMP043 | B4: NextGen Pharma | C4: 45645 | D4: Medium | E4: 8 days | F4: Delays from NextGen Pharma highlight systemic challenges, including forecasting inaccuracies and inventory mismanagement. These issues could disrupt production and hinder compliance with FDA regulations. | G4: NextGen Pharma faces challenges in aligning production schedules with customer demands. | H4: Medium risk with potential defects, highlighting a need for improved supplier communication. | I4: Engage NextGen Pharma to improve forecasting accuracy. Implement dynamic inventory replenishment models.
A6: 1. Average Delivery Timeline by Risk Level
A7: Risk Level | B7: Avg Delivery Timeline (Days)
A8: High | B8: =AVERAGEIF(Dataset!E:E,"High",Dataset!C:C) -> 11.25
A9: Medium | B9: =AVERAGEIF(Dataset!E:E,"Medium",Dataset!C:C) -> 15.125
A10: Low | B10: =AVERAGEIF(Dataset!E:E,"Low",Dataset!C:C) -> 12.857143
A12: 2. On-Time Delivery Rate for Delayed Components
A13: Component | B13: On-Time Delivery Rate (%) | C13: Count of Records
A14: CARB123 | B14: =AVERAGEIF(Dataset!A:A,"CARB123",Dataset!P:P) -> 90.25 | C14: =COUNTIF(Dataset!A:A,"CARB123") -> 4
A15: BIND567 | B15: =AVERAGEIF(Dataset!A:A,"BIND567",Dataset!P:P) -> 99 | C15: =COUNTIF(Dataset!A:A,"BIND567") -> 1
A16: COAT890 | B16: =AVERAGEIF(Dataset!A:A,"COAT890",Dataset!P:P) -> 84.2 | C16: =COUNTIF(Dataset!A:A,"COAT890") -> 5
A17: Overall Average | B17: =AVERAGE(B14:B16) -> 91.15 | C17: =SUM(C14:C16) -> 10
A19: 3. Supplier Performance Breakdown
A20: Supplier | B20: Avg On-Time Delivery (%) | C20: Avg Reliability (%) | D20: Avg Defect Rate (%) | E20: Avg Lead Time Variance (Days) | F20: Component Count
A21: EcoSupply | B21: =AVERAGEIF(Dataset!B:B,"EcoSupply",Dataset!P:P) -> 87.9 | C21: =AVERAGEIF(Dataset!B:B,"EcoSupply",Dataset!J:J) -> 93.2 | D21: =AVERAGEIF(Dataset!B:B,"EcoSupply",Dataset!H:H) -> 2.498 | E21: =AVERAGEIF(Dataset!B:B,"EcoSupply",Dataset!M:M) -> 7.4 | F21: =COUNTIF(Dataset!B:B,"EcoSupply") -> 10
A22: RawMatPlus | B22: =AVERAGEIF(Dataset!B:B,"RawMatPlus",Dataset!P:P) -> 90.615385 | C22: =AVERAGEIF(Dataset!B:B,"RawMatPlus",Dataset!J:J) -> 92.846154 | D22: =AVERAGEIF(Dataset!B:B,"RawMatPlus",Dataset!H:H) -> 2.5961538 | E22: =AVERAGEIF(Dataset!B:B,"RawMatPlus",Dataset!M:M) -> 6.7692308 | F22: =COUNTIF(Dataset!B:B,"RawMatPlus") -> 13
A23: GlobalChem | B23: =AVERAGEIF(Dataset!B:B,"GlobalChem",Dataset!P:P) -> 90.888889 | C23: =AVERAGEIF(Dataset!B:B,"GlobalChem",Dataset!J:J) -> 92.555556 | D23: =AVERAGEIF(Dataset!B:B,"GlobalChem",Dataset!H:H) -> 2.5677778 | E23: =AVERAGEIF(Dataset!B:B,"GlobalChem",Dataset!M:M) -> 7.5555556 | F23: =COUNTIF(Dataset!B:B,"GlobalChem") -> 9
A24: NextGen Pharma | B24: =AVERAGEIF(Dataset!B:B,"NextGen Pharma",Dataset!P:P) -> 91.545455 | C24: =AVERAGEIF(Dataset!B:B,"NextGen Pharma",Dataset!J:J) -> 91.818182 | D24: =AVERAGEIF(Dataset!B:B,"NextGen Pharma",Dataset!H:H) -> 2.2190909 | E24: =AVERAGEIF(Dataset!B:B,"NextGen Pharma",Dataset!M:M) -> 4.9090909 | F24: =COUNTIF(Dataset!B:B,"NextGen Pharma") -> 11
A25: PrimeLogistics | B25: =AVERAGEIF(Dataset!B:B,"PrimeLogistics",Dataset!P:P) -> 88 | C25: =AVERAGEIF(Dataset!B:B,"PrimeLogistics",Dataset!J:J) -> 91.428571 | D25: =AVERAGEIF(Dataset!B:B,"PrimeLogistics",Dataset!H:H) -> 2.8885714 | E25: =AVERAGEIF(Dataset!B:B,"PrimeLogistics",Dataset!M:M) -> 6.7142857 | F25: =COUNTIF(Dataset!B:B,"PrimeLogistics") -> 7
A27: 4. Identified Supply Chain Issues
A28: Issue Category | B28: Metric | C28: Threshold | D28: Affected Components | E28: Severity
A29: High Defect Rate | B29: Defect Rate > 3% | C29: 0.03 | D29: {=_xlfn.TEXTJOIN(", ", TRUE, IF(Dataset!H2:H51>3, Dataset!A2:A51, ""))} -> CARB123, COAT890, COAT890, COAT890, COAT890, COMP017, COMP019, COMP023, COMP024, COMP025, COMP026, COMP030, COMP036, COMP038, COMP043, COMP044, COMP048 | E29: High
A30: Poor On-Time Delivery | B30: On-Time Delivery < 85% | C30: 0.85 | D30: {=_xlfn.TEXTJOIN(", ", TRUE, IF(Dataset!P2:P51<85, Dataset!A2:A51, ""))} -> CARB123, COAT890, COAT890, COAT890, COMP012, COMP020, COMP029, COMP031, COMP035, COMP048 | E30: Critical
A31: Lead Time Variability | B31: Lead Time Variance > 8 days | C31: 8 days | D31: {=_xlfn.TEXTJOIN(", ", TRUE, IF(Dataset!M2:M51>8, Dataset!A2:A51, ""))} -> BIND567, CARB123, COAT890, COAT890, COMP010, COMP012, COMP016, COMP025, COMP026, COMP037, COMP040, COMP046 | E31: Medium
A32: Unreliable Suppliers | B32: Supplier Reliability < 90% | C32: 0.9 | D32: {=_xlfn.TEXTJOIN(", ", TRUE, IF(Dataset!J2:J51<90, Dataset!A2:A51, ""))} -> CARB123, CARB123, COAT890, COAT890, COMP010, COMP023, COMP024, COMP026, COMP035, COMP037, COMP047, COMP048, COMP049 | E32: High
A33: High Backorder Volume | B33: Backorder > 400 units | C33: 400 units | D33: {=_xlfn.TEXTJOIN(", ", TRUE, IF(Dataset!Q2:Q51>400, Dataset!A2:A51, ""))} -> BIND567, COAT890, COAT890, COMP013, COMP019, COMP020, COMP023, COMP030, COMP036, COMP037, COMP045, COMP048 | E33: Medium
A34: Poor Forecast Accuracy | B34: Forecast Accuracy < 85% | C34: 0.85 | D34: {=_xlfn.TEXTJOIN(", ", TRUE, IF(Dataset!S2:S51<85, Dataset!A2:A51, ""))} -> CARB123, COAT890, COAT890, COMP010, COMP012, COMP013, COMP014, COMP015, COMP017, COMP018, COMP019, COMP022, COMP031, COMP037, COMP038, COMP043, COMP045, COMP048 | E34: Medium
A36: 5. Key Metrics Summary
A37: Metric | B37: Value | C37: Status
A38: Components with Critical Issues (On-Time <85%) | B38: =COUNTIF(Dataset!P2:P51,"<85") -> 10 | C38: =IF(B38>5,"⚠️ Action Required","✓ Acceptable") -> ⚠️ Action Required
A39: Components with High Defect Rate (>3%) | B39: =COUNTIF(Dataset!H2:H51,">3") -> 17 | C39: =IF(B39>10,"⚠️ Action Required","✓ Acceptable") -> ⚠️ Action Required
A40: Average On-Time Delivery Rate | B40: =AVERAGE(Dataset!P2:P51) -> 89.96 | C40: =IF(B40<90,"⚠️ Below Target","✓ On Target") -> ⚠️ Below Target
A41: Average Supplier Reliability | B41: =AVERAGE(Dataset!J2:J51) -> 92.44 | C41: =IF(B41<92,"⚠️ Below Target","✓ On Target") -> ✓ On Target
A42: Total Backorder Volume | B42: =SUM(Dataset!Q2:Q51) -> 13232 | C42: =IF(B42>10000,"⚠️ High","✓ Manageable") -> ⚠️ High
A44: 6. Actionable Insights & Recommendations
A45: Priority | B45: Issue | C45: Recommendation | D45: Expected Impact
A46: 1 - Critical | B46: COAT890 has lowest on-time delivery (84.2%) | C46: Establish dual-sourcing with backup supplier; Implement expedited shipping protocols | D46: Improve delivery rate by 10-15%
...
